Workbook

Sheet SUMMARY
A1: TEN OUTSTANDING STUDENT AWARDS 2025
A2: ARASOF- Nasugbu Campus
A4: INDIVIDUAL SUMMARY SHEET
A6: LAST NAME:
A7: FIRST NAME, EXT.:
A8: MIDDLE NAME:
A9: COLLEGE/DEPARTMENT:
A10: PROGRAM:
A12: CRITERIA | F12: STUDENT SCORE
A13: CRITERION A - ACADEMIC (MAXIMUM = 40 POINTS)
A14: I. Grades / Scholastic Record (30 points) | F14: =Acad!G12 -> #N/A
A15: II. Academic Awards / Citations(10 points) | F15: =Acad!G97 -> 0
A16: TOTAL | F16: =MIN(SUM(MIN(F14,30),MIN(F15,10)),40) -> #N/A
A17: CRITERION B - LEADERSHIP (MAXIMUM = 30 POINTS)
A18: I. International (6 points) | F18: ='L1'!H71 -> 6
A19: II. National / Regional (12 points) | F19: ='L2'!H97 -> 12
A20: III. Local / Provincial (12 points) | F20: ='SC1'!H216 -> 18
A21: TOTAL | F21: =MIN((MIN(F18,6))+(MIN(F19,12))+(MIN(F20,12)),30) -> 30
A22: CRITERION C- SOCIAL RESPONSIBILITY (MAXIMUM = 30 POINTS)
A23: I. Non-School (18 oints) | F23: ='SC1'!H216 -> 18
A24: II. School (12 points) | F24: ='SC2'!H216 -> 12
A25: TOTAL | F25: =MIN(SUM(MIN(F23,18),MIN(F24,12)),30) -> 30
A27: EVALUATED BY:
A29: Ms. ANALYN H. VENZON | E29: Asst. Prof. CHERRY U. BANTA
A30: Name and Signature of TOSA Member | E30: Name and Signature of TOSA Member
A31: Date: | E31: Date:
C33: Dr. DYEMNAH INASIAH P. BENTIR
C34: Name and Signature of TOSA Member
C35: Date:

Sheet Acad
A1: TEN OUTSTANDING STUDENT AWARDS 2024 | H1: GWA | I1: Score
A2: ARASOF- Nasugbu Campus | H2: 1 | I2: 30
H3: 1.07 | I3: 29 | J3: First Place
A4: ACADEMIC | H4: 1.14 | I4: 28 | J4: Second Place
H5: 1.21 | I5: 27 | J5: Third Place
A6: LAST NAME: | C6: =SUMMARY!C6 | H6: 1.28 | I6: 26 | J6: Fourth Place
A7: FIRST NAME, EXT.: | C7: =SUMMARY!C7 | H7: 1.35 | I7: 25 | J7: Fifth Place
A8: MIDDLE NAME: | C8: =SUMMARY!C8 | H8: 1.41 | I8: 24 | J8: Sixth Place
H9: 1.48 | I9: 23 | J9: Seventh Place
A10: CRITERION A - ACADEMIC (MAXIMUM = 40 POINTS) | F10: GWA | G10: SCORE | H10: 1.55 | I10: 22 | J10: Eighth Place
A11: I. Grades / Scholastic Record (30 points) | G11: =LOOKUP(F11, H2:H31, I2:I31) -> #N/A | H11: 1.62 | I11: 21 | J11: Ninth Place
A12: TOTAL | G12: =(MIN(SUM(G11),30)) -> #N/A | H12: 1.69 | I12: 20 | J12: Tenth Place
H13: 1.76 | I13: 19
A14: II. Academic Awards / Citations(10 points) (Refers to Quiz Bees, Research Presentations, Journalism and other academic related awards) | H14: 1.83 | I14: 18
A15: International | H15: 1.9 | I15: 17
A16: Name of the Awarding Body | C16: Title of the Award | F16: Place | G16: Point | H16: 1.97 | I16: 16
G17: =IF(F17="", "", IF(F17="First Place", 3, IF(F17="Second Place", 2, IF(F17="Third Place", 1, IF(OR(F17="Fourth Place", F17="Fifth Place", F17="Sixth Place", F17="Seventh Place", F17="Eighth Place", F17="Ninth Place", F17="Tenth Place"), 0.5, 0))))) | H17: 2.03 | I17: 15
G18: =IF(F18="", "", IF(F18="First Place", 3, IF(F18="Second Place", 2, IF(F18="Third Place", 1, IF(OR(F18="Fourth Place", F18="Fifth Place", F18="Sixth Place", F18="Seventh Place", F18="Eighth Place", F18="Ninth Place", F18="Tenth Place"), 0.5, 0))))) | H18: 2.1 | I18: 14
G19: =IF(F19="", "", IF(F19="First Place", 3, IF(F19="Second Place", 2, IF(F19="Third Place", 1, IF(OR(F19="Fourth Place", F19="Fifth Place", F19="Sixth Place", F19="Seventh Place", F19="Eighth Place", F19="Ninth Place", F19="Tenth Place"), 0.5, 0))))) | H19: 2.17 | I19: 13
G20: =IF(F20="", "", IF(F20="First Place", 3, IF(F20="Second Place", 2, IF(F20="Third Place", 1, IF(OR(F20="Fourth Place", F20="Fifth Place", F20="Sixth Place", F20="Seventh Place", F20="Eighth Place", F20="Ninth Place", F20="Tenth Place"), 0.5, 0))))) | H20: 2.24 | I20: 12
G21: =IF(F21="", "", IF(F21="First Place", 3, IF(F21="Second Place", 2, IF(F21="Third Place", 1, IF(OR(F21="Fourth Place", F21="Fifth Place", F21="Sixth Place", F21="Seventh Place", F21="Eighth Place", F21="Ninth Place", F21="Tenth Place"), 0.5, 0))))) | H21: 2.31 | I21: 11
G22: =IF(F22="", "", IF(F22="First Place", 3, IF(F22="Second Place", 2, IF(F22="Third Place", 1, IF(OR(F22="Fourth Place", F22="Fifth Place", F22="Sixth Place", F22="Seventh Place", F22="Eighth Place", F22="Ninth Place", F22="Tenth Place"), 0.5, 0))))) | H22: 2.38 | I22: 10
G23: =IF(F23="", "", IF(F23="First Place", 3, IF(F23="Second Place", 2, IF(F23="Third Place", 1, IF(OR(F23="Fourth Place", F23="Fifth Place", F23="Sixth Place", F23="Seventh Place", F23="Eighth Place", F23="Ninth Place", F23="Tenth Place"), 0.5, 0))))) | H23: 2.45 | I23: 9
G24: =IF(F24="", "", IF(F24="First Place", 3, IF(F24="Second Place", 2, IF(F24="Third Place", 1, IF(OR(F24="Fourth Place", F24="Fifth Place", F24="Sixth Place", F24="Seventh Place", F24="Eighth Place", F24="Ninth Place", F24="Tenth Place"), 0.5, 0))))) | H24: 2.52 | I24: 8
G25: =IF(F25="", "", IF(F25="First Place", 3, IF(F25="Second Place", 2, IF(F25="Third Place", 1, IF(OR(F25="Fourth Place", F25="Fifth Place", F25="Sixth Place", F25="Seventh Place", F25="Eighth Place", F25="Ninth Place", F25="Tenth Place"), 0.5, 0))))) | H25: 2.59 | I25: 7
G26: =IF(F26="", "", IF(F26="First Place", 3, IF(F26="Second Place", 2, IF(F26="Third Place", 1, IF(OR(F26="Fourth Place", F26="Fifth Place", F26="Sixth Place", F26="Seventh Place", F26="Eighth Place", F26="Ninth Place", F26="Tenth Place"), 0.5, 0))))) | H26: 2.66 | I26: 6
G27: =IF(F27="", "", IF(F27="First Place", 3, IF(F27="Second Place", 2, IF(F27="Third Place", 1, IF(OR(F27="Fourth Place", F27="Fifth Place", F27="Sixth Place", F27="Seventh Place", F27="Eighth Place", F27="Ninth Place", F27="Tenth Place"), 0.5, 0))))) | H27: 2.72 | I27: 5
G28: =IF(F28="", "", IF(F28="First Place", 3, IF(F28="Second Place", 2, IF(F28="Third Place", 1, IF(OR(F28="Fourth Place", F28="Fifth Place", F28="Sixth Place", F28="Seventh Place", F28="Eighth Place", F28="Ninth Place", F28="Tenth Place"), 0.5, 0))))) | H28: 2.79 | I28: 4
... G31: =IF(F31="", "", IF(F31="First Place", 3, IF(F31="Second Place", 2, IF(F31="Third Place", 1, IF(OR(F31="Fourth Place", F31="Fifth Place", F31="Sixth Place", F31="Seventh Place", F31="Eighth Place", F31="Ninth Place", F31="Tenth Place"), 0.5, 0))))) | H31: 3 | I31: 1
G32: =IF(F32="", "", IF(F32="First Place", 3, IF(F32="Second Place", 2, IF(F32="Third Place", 1, IF(OR(F32="Fourth Place", F32="Fifth Place", F32="Sixth Place", F32="Seventh Place", F32="Eighth Place", F32="Ninth Place", F32="Tenth Place"), 0.5, 0)))))
G33: =IF(F33="", "", IF(F33="First Place", 3, IF(F33="Second Place", 2, IF(F33="Third Place", 1, IF(OR(F33="Fourth Place", F33="Fifth Place", F33="Sixth Place", F33="Seventh Place", F33="Eighth Place", F33="Ninth Place", F33="Tenth Place"), 0.5, 0)))))
G34: =IF(F34="", "", IF(F34="First Place", 3, IF(F34="Second Place", 2, IF(F34="Third Place", 1, IF(OR(F34="Fourth Place", F34="Fifth Place", F34="Sixth Place", F34="Seventh Place", F34="Eighth Place", F34="Ninth Place", F34="Tenth Place"), 0.5, 0)))))
G35: =IF(F35="", "", IF(F35="First Place", 3, IF(F35="Second Place", 2, IF(F35="Third Place", 1, IF(OR(F35="Fourth Place", F35="Fifth Place", F35="Sixth Place", F35="Seventh Place", F35="Eighth Place", F35="Ninth Place", F35="Tenth Place"), 0.5, 0)))))
A36: SUB-TOTAL | G36: =SUM(G17:G35) -> 0
A37: National/Regional
A38: Name of the Awarding Body | C38: Title of the Award | F38: Place | G38: Point
G39: =IF(F39="", "", IF(F39="First Place", 2, IF(F39="Second Place", 1, IF(F39="Third Place", 0.5, IF(OR(F39="Fourth Place", F39="Fifth Place", F39="Sixth Place", F39="Seventh Place", F39="Eighth Place", F39="Ninth Place", F39="Tenth Place"), 0.25, 0)))))
G40: =IF(F40="", "", IF(F40="First Place", 2, IF(F40="Second Place", 1, IF(F40="Third Place", 0.5, IF(OR(F40="Fourth Place", F40="Fifth Place", F40="Sixth Place", F40="Seventh Place", F40="Eighth Place", F40="Ninth Place", F40="Tenth Place"), 0.25, 0)))))
G41: =IF(F41="", "", IF(F41="First Place", 2, IF(F41="Second Place", 1, IF(F41="Third Place", 0.5, IF(OR(F41="Fourth Place", F41="Fifth Place", F41="Sixth Place", F41="Seventh Place", F41="Eighth Place", F41="Ninth Place", F41="Tenth Place"), 0.25, 0)))))
G42: =IF(F42="", "", IF(F42="First Place", 2, IF(F42="Second Place", 1, IF(F42="Third Place", 0.5, IF(OR(F42="Fourth Place", F42="Fifth Place", F42="Sixth Place", F42="Seventh Place", F42="Eighth Place", F42="Ninth Place", F42="Tenth Place"), 0.25, 0)))))
...

Sheet L1
A1: TEN OUTSTANDING STUDENT AWARDS 2024 | I1: GWA | J1: Score
A2: ARASOF- Nasugbu Campus | I2: 1 | J2: 30
I3: 1.07 | J3: 29 | K3: First Place
A4: LEADERSHIP | I4: 1.14 | J4: 28 | K4: Second Place
I5: 1.21 | J5: 27 | K5: Third Place
A6: LAST NAME: | D6: =SUMMARY!C6 | I6: 1.28 | J6: 26 | K6: Fourth Place
A7: FIRST NAME, EXT.: | D7: =SUMMARY!C7 | I7: 1.35 | J7: 25 | K7: Fifth Place
A8: MIDDLE NAME: | D8: =SUMMARY!C8 | I8: 1.41 | J8: 24 | K8: Sixth Place
I9: 1.48 | J9: 23 | K9: Seventh Place
A10: CRITERION B - LEADERSHIP (MAXIMUM = 30 POINTS) | I10: 1.55 | J10: 22 | K10: Eighth Place
A11: B.1 International (6 points)
A12: B.1.1. Workshop and Seminars attended related to Leadership
A13: Inclusive Date of Attendance (Starting Date) DD/MM/YYYY | B13: Inclusive Date of Attendance (End date) DD/MM/YYYY | C13: Title of WorkShop/Seminar Attended | F13: Organizer | H13: Point
H14: =MIN(K14* 0.6, 3) -> 0 | K14: =B14-A14 -> 0
H15: =MIN(K15* 0.6, 3) -> 0 | K15: =B15-A15 -> 0
H16: =MIN(K16* 0.6, 3) -> 0 | K16: =B16-A16 -> 0
H17: =MIN(K17* 0.6, 3) -> 0 | K17: =B17-A17 -> 0
H18: =MIN(K18* 0.6, 3) -> 0 | K18: =B18-A18 -> 0
H19: =MIN(K19* 0.6, 3) -> 0 | K19: =B19-A19 -> 0
H20: =MIN(K20* 0.6, 3) -> 0 | K20: =B20-A20 -> 0
H21: =MIN(K21* 0.6, 3) -> 0 | K21: =B21-A21 -> 0
H22: =MIN(K22* 0.6, 3) -> 0 | K22: =B22-A22 -> 0
H23: =MIN(K23* 0.6, 3) -> 0 | K23: =B23-A23 -> 0
H24: =MIN(K24* 0.6, 3) -> 0 | K24: =B24-A24 -> 0
H25: =MIN(K25* 0.6, 3) -> 0 | K25: =B25-A25 -> 0
... H43: =MIN(K43* 0.6, 3) -> 0 | K43: =B43-A43 -> 0
A44: SUB-TOTAL | H44: =SUM(H13:H43) -> 0
A45: B.1.2 Leadership in Organizations
A46: Position | C46: Organization | H46: Point
H47: =IF(A47="", "", IF(A47="President",1,IF(A47="Vice President",0.75,0.5))) | I47: President
H48: =IF(A48="", "", IF(A48="President",1,IF(A48="Vice President",0.75,0.5))) | I48: Vice President
H49: =IF(A49="", "", IF(A49="President",1,IF(A49="Vice President",0.75,0.5))) | I49: Other Positions
H50: =IF(A50="", "", IF(A50="President",1,IF(A50="Vice President",0.75,0.5)))
H51: =IF(A51="", "", IF(A51="President",1,IF(A51="Vice President",0.75,0.5)))
H52: =IF(A52="", "", IF(A52="President",1,IF(A52="Vice President",0.75,0.5)))
H53: =IF(A53="", "", IF(A53="President",1,IF(A53="Vice President",0.75,0.5)))
H54: =IF(A54="", "", IF(A54="President",1,IF(A54="Vice President",0.75,0.5)))
H55: =IF(A55="", "", IF(A55="President",1,IF(A55="Vice President",0.75,0.5)))
H56: =IF(A56="", "", IF(A56="President",1,IF(A56="Vice President",0.75,0.5)))
H57: =IF(A57="", "", IF(A57="President",1,IF(A57="Vice President",0.75,0.5)))
...

Sheet L2
A1: TEN OUTSTANDING STUDENT AWARDS 2024 | I1: GWA | J1: Score
A2: ARASOF- Nasugbu Campus | I2: 1 | J2: 30
I3: 1.07 | J3: 29 | K3: First Place
A4: LEADERSHIP | I4: 1.14 | J4: 28 | K4: Second Place
I5: 1.21 | J5: 27 | K5: Third Place
A6: LAST NAME: | D6: =SUMMARY!C6 | I6: 1.28 | J6: 26 | K6: Fourth Place
A7: FIRST NAME, EXT.: | D7: =SUMMARY!C7 | I7: 1.35 | J7: 25 | K7: Fifth Place
A8: MIDDLE NAME: | D8: =SUMMARY!C8 | I8: 1.41 | J8: 24 | K8: Sixth Place
I9: 1.48 | J9: 23 | K9: Seventh Place
A10: CRITERION B - LEADERSHIP (MAXIMUM = 30 POINTS) | I10: 1.55 | J10: 22 | K10: Eighth Place
A11: B.2.1 National/Regional (12 points)
A12: B.1.1. Workshop and Seminars attended related to Leadership
A13: Inclusive Date of Attendance (Starting Date) DD/MM/YYYY | B13: Inclusive Date of Attendance (End date) DD/MM/YYYY | C13: Title of WorkShop/Seminar Attended | F13: Organizer | H13: Point
H14: =MIN(K14* 0.4, 2) -> 0 | K14: =B14-A14 -> 0 | L14: =0.2*5 -> 1
H15: =MIN(K15* 0.4, 2) -> 0 | K15: =B15-A15 -> 0
H16: =MIN(K16* 0.4, 2) -> 0 | K16: =B16-A16 -> 0
H17: =MIN(K17* 0.4, 2) -> 0 | K17: =B17-A17 -> 0
H18: =MIN(K18* 0.4, 2) -> 0 | K18: =B18-A18 -> 0
H19: =MIN(K19* 0.4, 2) -> 0 | K19: =B19-A19 -> 0
H20: =MIN(K20* 0.4, 2) -> 0 | K20: =B20-A20 -> 0
H21: =MIN(K21* 0.4, 2) -> 0 | K21: =B21-A21 -> 0
H22: =MIN(K22* 0.4, 2) -> 0 | K22: =B22-A22 -> 0
H23: =MIN(K23* 0.4, 2) -> 0 | K23: =B23-A23 -> 0
H24: =MIN(K24* 0.4, 2) -> 0 | K24: =B24-A24 -> 0
H25: =MIN(K25* 0.4, 2) -> 0 | K25: =B25-A25 -> 0
H26: =MIN(K26* 0.4, 2) -> 0 | K26: =B26-A26 -> 0
... H53: =MIN(K53* 0.4, 2) -> 0 | K53: =B53-A53 -> 0
A54: SUB-TOTAL | H54: =SUM(H14:H53) -> 0
A55: B.2.2 Leadership in Organizations
A56: Position | C56: Organization | H56: Point
H57: =IF(A57="", "", IF(A57="President",0.75,IF(A57="Vice President",0.5,0.25))) | I57: President
H58: =IF(A58="", "", IF(A58="President",0.75,IF(A58="Vice President",0.5,0.25))) | I58: Vice President
H59: =IF(A59="", "", IF(A59="President",0.75,IF(A59="Vice President",0.5,0.25)))
H60: =IF(A60="", "", IF(A60="President",0.75,IF(A60="Vice President",0.5,0.25)))
H61: =IF(A61="", "", IF(A61="President",0.75,IF(A61="Vice President",0.5,0.25)))
H62: =IF(A62="", "", IF(A62="President",0.75,IF(A62="Vice President",0.5,0.25)))
H63: =IF(A63="", "", IF(A63="President",0.75,IF(A63="Vice President",0.5,0.25)))
H64: =IF(A64="", "", IF(A64="President",0.75,IF(A64="Vice President",0.5,0.25)))
H65: =IF(A65="", "", IF(A65="President",0.75,IF(A65="Vice President",0.5,0.25)))
H66: =IF(A66="", "", IF(A66="President",0.75,IF(A66="Vice President",0.5,0.25)))
...

Sheet L3
A1: TEN OUTSTANDING STUDENT AWARDS 2024 | I1: GWA | J1: Score
A2: ARASOF- Nasugbu Campus | I2: 1 | J2: 30
I3: 1.07 | J3: 29 | K3: First Place
A4: LEADERSHIP | I4: 1.14 | J4: 28 | K4: Second Place
I5: 1.21 | J5: 27 | K5: Third Place
A6: LAST NAME: | D6: =SUMMARY!C6 | I6: 1.28 | J6: 26 | K6: Fourth Place
A7: FIRST NAME, EXT.: | D7: =SUMMARY!C7 | I7: 1.35 | J7: 25 | K7: Fifth Place
A8: MIDDLE NAME: | D8: =SUMMARY!C8 | I8: 1.41 | J8: 24 | K8: Sixth Place
I9: 1.48 | J9: 23 | K9: Seventh Place
A10: CRITERION B - LEADERSHIP (MAXIMUM = 30 POINTS) | I10: 1.55 | J10: 22 | K10: Eighth Place
A11: B.3.1 Local/Provincial (12 points)
A12: B.3.1. Workshop and Seminars attended related to Leadership
A13: Inclusive Date of Attendance (Starting Date) DD/MM/YYYY | B13: Inclusive Date of Attendance (End date) DD/MM/YYYY | C13: Title of WorkShop/Seminar Attended | F13: Organizer | H13: Point
H14: =MIN(K14* 0.2, 1) -> 0 | K14: =B14-A14 -> 0 | L14: =0.2*5 -> 1
H15: =MIN(K15* 0.2, 1) -> 0 | K15: =B15-A15 -> 0
H16: =MIN(K16* 0.2, 1) -> 0 | K16: =B16-A16 -> 0
H17: =MIN(K17* 0.2, 1) -> 0 | K17: =B17-A17 -> 0
H18: =MIN(K18* 0.2, 1) -> 0 | K18: =B18-A18 -> 0
H19: =MIN(K19* 0.2, 1) -> 0 | K19: =B19-A19 -> 0
H20: =MIN(K20* 0.2, 1) -> 0 | K20: =B20-A20 -> 0
H21: =MIN(K21* 0.2, 1) -> 0 | K21: =B21-A21 -> 0
H22: =MIN(K22* 0.2, 1) -> 0 | K22: =B22-A22 -> 0
H23: =MIN(K23* 0.2, 1) -> 0 | K23: =B23-A23 -> 0
H24: =MIN(K24* 0.2, 1) -> 0 | K24: =B24-A24 -> 0
H25: =MIN(K25* 0.2, 1) -> 0 | K25: =B25-A25 -> 0
H26: =MIN(K26* 0.2, 1) -> 0 | K26: =B26-A26 -> 0
... H73: =MIN(K73* 0.2, 1) -> 0 | K73: =B73-A73 -> 0
A74: SUB-TOTAL | H74: =SUM(H14:H73) -> 0
A75: B.3.2 Leadership in Organizations
A76: Position | C76: Organization | H76: Point
H77: =IF(A77="", "", IF(A77="President",0.5,IF(A77="Vice President",0.25,0.125))) | I77: President
H78: =IF(A78="", "", IF(A78="President",0.75,IF(A78="Vice President",0.5,0.25))) | I78: Vice President
H79: =IF(A79="", "", IF(A79="President",0.75,IF(A79="Vice President",0.5,0.25)))
H80: =IF(A80="", "", IF(A80="President",0.75,IF(A80="Vice President",0.5,0.25)))
H81: =IF(A81="", "", IF(A81="President",0.75,IF(A81="Vice President",0.5,0.25)))
H82: =IF(A82="", "", IF(A82="President",0.75,IF(A82="Vice President",0.5,0.25)))
H83: =IF(A83="", "", IF(A83="President",0.75,IF(A83="Vice President",0.5,0.25)))
H84: =IF(A84="", "", IF(A84="President",0.75,IF(A84="Vice President",0.5,0.25)))
H85: =IF(A85="", "", IF(A85="President",0.75,IF(A85="Vice President",0.5,0.25)))
H86: =IF(A86="", "", IF(A86="President",0.75,IF(A86="Vice President",0.5,0.25)))
...

Sheet SC1
A1: TEN OUTSTANDING STUDENT AWARDS 2024 | I1: GWA | J1: Score
A2: ARASOF- Nasugbu Campus | I2: 1 | J2: 30
I3: 1.07 | J3: 29 | K3: First Place
A4: SOCIAL RESPONSIBILITY | I4: 1.14 | J4: 28 | K4: Second Place
I5: 1.21 | J5: 27 | K5: Third Place
A6: LAST NAME: | D6: =SUMMARY!C6 | I6: 1.28 | J6: 26 | K6: Fourth Place
A7: FIRST NAME, EXT.: | D7: =SUMMARY!C7 | I7: 1.35 | J7: 25 | K7: Fifth Place
A8: MIDDLE NAME: | D8: =SUMMARY!C8 | I8: 1.41 | J8: 24 | K8: Sixth Place
I9: 1.48 | J9: 23 | K9: Seventh Place
A10: CRITERION C - SOCIAL RESPONSIBILITY (MAXIMUM = 30 POINTS) | I10: 1.55 | J10: 22 | K10: Eighth Place
A11: C.1 (18 points)
A12: C.1.1 (International)
A13: Inclusive Date of Attendance DD/MM/YYYY | B13: Nature or Description of Activity | C13: Name of Organization | F13: Role | H13: Point
F14: Organizer | H14: {=IFS(F14="", "",F14="Organizer", 3, F14="Team Leader", 3, F14="Participant", 1.5, F14="Performer", 1.5)} -> 3 | I14: Organizer | K14: =B14-A14 -> 0 | L14: =0.2*5 -> 1
F15: Team Leader | H15: {=IFS(F15="", "",F15="Organizer", 3, F15="Team Leader", 3, F15="Participant", 1.5, F15="Performer", 1.5)} -> 3 | I15: Team Leader | K15: =B15-A15 -> 0
F16: Organizer | H16: {=IFS(F16="", "",F16="Organizer", 3, F16="Team Leader", 3, F16="Participant", 1.5, F16="Performer", 1.5)} -> 3 | I16: Participant | K16: =B16-A16 -> 0
F17: Organizer | H17: {=IFS(F17="", "",F17="Organizer", 3, F17="Team Leader", 3, F17="Participant", 1.5, F17="Performer", 1.5)} -> 3 | I17: Performer | K17: =B17-A17 -> 0
F18: Organizer | H18: {=IFS(F18="", "",F18="Organizer", 3, F18="Team Leader", 3, F18="Participant", 1.5, F18="Performer", 1.5)} -> 3 | K18: =B18-A18 -> 0
F19: Organizer | H19: {=IFS(F19="", "",F19="Organizer", 3, F19="Team Leader", 3, F19="Participant", 1.5, F19="Performer", 1.5)} -> 3 | K19: =B19-A19 -> 0
F20: Organizer | H20: {=IFS(F20="", "",F20="Organizer", 3, F20="Team Leader", 3, F20="Participant", 1.5, F20="Performer", 1.5)} -> 3 | K20: =B20-A20 -> 0
F21: Organizer | H21: {=IFS(F21="", "",F21="Organizer", 3, F21="Team Leader", 3, F21="Participant", 1.5, F21="Performer", 1.5)} -> 3 | K21: =B21-A21 -> 0
F22: Organizer | H22: {=IFS(F22="", "",F22="Organizer", 3, F22="Team Leader", 3, F22="Participant", 1.5, F22="Performer", 1.5)} -> 3 | K22: =B22-A22 -> 0
H23: {=IFS(F23="", "",F23="Organizer", 3, F23="Team Leader", 3, F23="Participant", 1.5, F23="Performer", 1.5)} | K23: =B23-A23 -> 0
H24: {=IFS(F24="", "",F24="Organizer", 3, F24="Team Leader", 3, F24="Participant", 1.5, F24="Performer", 1.5)} | K24: =B24-A24 -> 0
H25: {=IFS(F25="", "",F25="Organizer", 3, F25="Team Leader", 3, F25="Participant", 1.5, F25="Performer", 1.5)} | K25: =B25-A25 -> 0
H26: {=IFS(F26="", "",F26="Organizer", 3, F26="Team Leader", 3, F26="Participant", 1.5, F26="Performer", 1.5)} | K26: =B26-A26 -> 0
H27: {=IFS(F27="", "",F27="Organizer", 3, F27="Team Leader", 3, F27="Participant", 1.5, F27="Performer", 1.5)} | K27: =B27-A27 -> 0
H28: {=IFS(F28="", "",F28="Organizer", 3, F28="Team Leader", 3, F28="Participant", 1.5, F28="Performer", 1.5)} | K28: =B28-A28 -> 0
H29: {=IFS(F29="", "",F29="Organizer", 3, F29="Team Leader", 3, F29="Participant", 1.5, F29="Performer", 1.5)} | K29: =B29-A29 -> 0
H30: {=IFS(F30="", "",F30="Organizer", 3, F30="Team Leader", 3, F30="Participant", 1.5, F30="Performer", 1.5)} | K30: =B30-A30 -> 0
H31: {=IFS(F31="", "",F31="Organizer", 3, F31="Team Leader", 3, F31="Participant", 1.5, F31="Performer", 1.5)} | K31: =B31-A31 -> 0
H32: {=IFS(F32="", "",F32="Organizer", 3, F32="Team Leader", 3, F32="Participant", 1.5, F32="Performer", 1.5)} | K32: =B32-A32 -> 0
H33: {=IFS(F33="", "",F33="Organizer", 3, F33="Team Leader", 3, F33="Participant", 1.5, F33="Performer", 1.5)} | K33: =B33-A33 -> 0
H34: {=IFS(F34="", "",F34="Organizer", 3, F34="Team Leader", 3, F34="Participant", 1.5, F34="Performer", 1.5)} | K34: =B34-A34 -> 0
... H50: {=IFS(F50="", "",F50="Organizer", 3, F50="Team Leader", 3, F50="Participant", 1.5, F50="Performer", 1.5)} | K50: =B50-A50 -> 0
A51: SUB-TOTAL | H51: =SUM(H14:H50) -> 27
A52: C.1.2 (National/Regional)
A53: Inclusive Date of Attendance DD/MM/YYYY | B53: Nature or Description of Activity | C53: Name of Organization | F53: Role | H53: Point
F54: Organizer | H54: {=IFS(F54="", "",F54="Organizer", 2, F54="Team Leader", 2, F54="Participant", 1, F54="Performer", 1)} -> 2
F55: Team Leader | H55: {=IFS(F55="", "",F55="Organizer", 2, F55="Team Leader", 2, F55="Participant", 1, F55="Performer", 1)} -> 2
...

Sheet SC2
A1: TEN OUTSTANDING STUDENT AWARDS 2024 | I1: GWA | J1: Score
A2: ARASOF- Nasugbu Campus | I2: 1 | J2: 30
I3: 1.07 | J3: 29 | K3: First Place
A4: SOCIAL RESPONSIBILITY | I4: 1.14 | J4: 28 | K4: Second Place
I5: 1.21 | J5: 27 | K5: Third Place
A6: LAST NAME: | D6: =SUMMARY!C6 | I6: 1.28 | J6: 26 | K6: Fourth Place
A7: FIRST NAME, EXT.: | D7: =SUMMARY!C7 | I7: 1.35 | J7: 25 | K7: Fifth Place
A8: MIDDLE NAME: | D8: =SUMMARY!C8 | I8: 1.41 | J8: 24 | K8: Sixth Place
I9: 1.48 | J9: 23 | K9: Seventh Place
A10: CRITERION C - SOCIAL RESPONSIBILITY (MAXIMUM = 30 POINTS) | I10: 1.55 | J10: 22 | K10: Eighth Place
A11: C.2 School (12 points)
A12: C.2.1 (International)
A13: Inclusive Date of Attendance DD/MM/YYYY | B13: Nature or Description of Activity | C13: Name of Organization | F13: Role | H13: Point
F14: Organizer | H14: {=IFS(F14="", "",F14="Organizer", 3, F14="Team Leader", 3, F14="Participant", 1.5, F14="Performer", 1.5)} -> 3 | I14: Organizer | K14: =B14-A14 -> 0 | L14: =0.2*5 -> 1
F15: Team Leader | H15: {=IFS(F15="", "",F15="Organizer", 3, F15="Team Leader", 3, F15="Participant", 1.5, F15="Performer", 1.5)} -> 3 | I15: Team Leader | K15: =B15-A15 -> 0
F16: Organizer | H16: {=IFS(F16="", "",F16="Organizer", 3, F16="Team Leader", 3, F16="Participant", 1.5, F16="Performer", 1.5)} -> 3 | I16: Participant | K16: =B16-A16 -> 0
F17: Organizer | H17: {=IFS(F17="", "",F17="Organizer", 3, F17="Team Leader", 3, F17="Participant", 1.5, F17="Performer", 1.5)} -> 3 | I17: Performer | K17: =B17-A17 -> 0
F18: Organizer | H18: {=IFS(F18="", "",F18="Organizer", 3, F18="Team Leader", 3, F18="Participant", 1.5, F18="Performer", 1.5)} -> 3 | K18: =B18-A18 -> 0
F19: Organizer | H19: {=IFS(F19="", "",F19="Organizer", 3, F19="Team Leader", 3, F19="Participant", 1.5, F19="Performer", 1.5)} -> 3 | K19: =B19-A19 -> 0
F20: Organizer | H20: {=IFS(F20="", "",F20="Organizer", 3, F20="Team Leader", 3, F20="Participant", 1.5, F20="Performer", 1.5)} -> 3 | K20: =B20-A20 -> 0
F21: Organizer | H21: {=IFS(F21="", "",F21="Organizer", 3, F21="Team Leader", 3, F21="Participant", 1.5, F21="Performer", 1.5)} -> 3 | K21: =B21-A21 -> 0
F22: Organizer | H22: {=IFS(F22="", "",F22="Organizer", 3, F22="Team Leader", 3, F22="Participant", 1.5, F22="Performer", 1.5)} -> 3 | K22: =B22-A22 -> 0
H23: {=IFS(F23="", "",F23="Organizer", 3, F23="Team Leader", 3, F23="Participant", 1.5, F23="Performer", 1.5)} | K23: =B23-A23 -> 0
H24: {=IFS(F24="", "",F24="Organizer", 3, F24="Team Leader", 3, F24="Participant", 1.5, F24="Performer", 1.5)} | K24: =B24-A24 -> 0
H25: {=IFS(F25="", "",F25="Organizer", 3, F25="Team Leader", 3, F25="Participant", 1.5, F25="Performer", 1.5)} | K25: =B25-A25 -> 0
H26: {=IFS(F26="", "",F26="Organizer", 3, F26="Team Leader", 3, F26="Participant", 1.5, F26="Performer", 1.5)} | K26: =B26-A26 -> 0
H27: {=IFS(F27="", "",F27="Organizer", 3, F27="Team Leader", 3, F27="Participant", 1.5, F27="Performer", 1.5)} | K27: =B27-A27 -> 0
H28: {=IFS(F28="", "",F28="Organizer", 3, F28="Team Leader", 3, F28="Participant", 1.5, F28="Performer", 1.5)} | K28: =B28-A28 -> 0
H29: {=IFS(F29="", "",F29="Organizer", 3, F29="Team Leader", 3, F29="Participant", 1.5, F29="Performer", 1.5)} | K29: =B29-A29 -> 0
H30: {=IFS(F30="", "",F30="Organizer", 3, F30="Team Leader", 3, F30="Participant", 1.5, F30="Performer", 1.5)} | K30: =B30-A30 -> 0
H31: {=IFS(F31="", "",F31="Organizer", 3, F31="Team Leader", 3, F31="Participant", 1.5, F31="Performer", 1.5)} | K31: =B31-A31 -> 0
H32: {=IFS(F32="", "",F32="Organizer", 3, F32="Team Leader", 3, F32="Participant", 1.5, F32="Performer", 1.5)} | K32: =B32-A32 -> 0
H33: {=IFS(F33="", "",F33="Organizer", 3, F33="Team Leader", 3, F33="Participant", 1.5, F33="Performer", 1.5)} | K33: =B33-A33 -> 0
H34: {=IFS(F34="", "",F34="Organizer", 3, F34="Team Leader", 3, F34="Participant", 1.5, F34="Performer", 1.5)} | K34: =B34-A34 -> 0
... H50: {=IFS(F50="", "",F50="Organizer", 3, F50="Team Leader", 3, F50="Participant", 1.5, F50="Performer", 1.5)} | K50: =B50-A50 -> 0
A51: SUB-TOTAL | H51: =SUM(H14:H50) -> 27
A52: C.2.2 (National/Regional)
A53: Inclusive Date of Attendance DD/MM/YYYY | B53: Nature or Description of Activity | C53: Name of Organization | F53: Role | H53: Point
F54: Organizer | H54: {=IFS(F54="", "",F54="Organizer", 2, F54="Team Leader", 2, F54="Participant", 1, F54="Performer", 1)} -> 2
F55: Team Leader | H55: {=IFS(F55="", "",F55="Organizer", 2, F55="Team Leader", 2, F55="Participant", 1, F55="Performer", 1)} -> 2
...
